<sdf version='1.6'>
  <world name='default'>
    <light name='sun' type='directional'>
      <cast_shadows>1</cast_shadows>
      <pose frame=''>0 0 10 0 -0 0</pose>
      <diffuse>0.8 0.8 0.8 1</diffuse>
      <specular>0.2 0.2 0.2 1</specular>
      <attenuation>
        <range>1000</range>
        <constant>0.9</constant>
        <linear>0.01</linear>
        <quadratic>0.001</quadratic>
      </attenuation>
      <direction>-0.5 0.1 -0.9</direction>
    </light>
    <model name='ground_plane'>
      <static>1</static>
      <link name='link'>
        <collision name='collision'>
          <geometry>
            <plane>
              <normal>0 0 1</normal>
              <size>100 100</size>
            </plane>
          </geometry>
          <surface>
            <friction>
              <ode>
                <mu>100</mu>
                <mu2>50</mu2>
              </ode>
              <torsional>
                <ode/>
              </torsional>
            </friction>
            <contact>
              <ode/>
            </contact>
            <bounce/>
          </surface>
          <max_contacts>10</max_contacts>
        </collision>
        <visual name='visual'>
          <cast_shadows>0</cast_shadows>
          <geometry>
            <plane>
              <normal>0 0 1</normal>
              <size>100 100</size>
            </plane>
          </geometry>
          <material>
            <script>
              <uri>file://media/materials/scripts/gazebo.material</uri>
              <name>Gazebo/Grey</name>
            </script>
          </material>
        </visual>
        <self_collide>0</self_collide>
        <enable_wind>0</enable_wind>
        <kinematic>0</kinematic>
      </link>
    </model>
    <gravity>0 0 -9.8</gravity>
    <magnetic_field>6e-06 2.3e-05 -4.2e-05</magnetic_field>
    <atmosphere type='adiabatic'/>
    <physics name='default_physics' default='0' type='ode'>
      <max_step_size>0.001</max_step_size>
      <real_time_factor>1</real_time_factor>
      <real_time_update_rate>1000</real_time_update_rate>
    </physics>
    <scene>
      <ambient>0.4 0.4 0.4 1</ambient>
      <background>0.7 0.7 0.7 1</background>
      <shadows>1</shadows>
    </scene>
    <audio>
      <device>default</device>
    </audio>
    <wind/>
    <spherical_coordinates>
      <surface_model>EARTH_WGS84</surface_model>
      <latitude_deg>0</latitude_deg>
      <longitude_deg>0</longitude_deg>
      <elevation>0</elevation>
      <heading_deg>0</heading_deg>
    </spherical_coordinates>
    <model name='robot'>
      <link name='base_link'>
        <pose frame=''>0 0 0 0 -0 0</pose>
        <inertial>
          <pose frame=''>0 0 0 0 -0 0</pose>
          <mass>4</mass>
          <inertia>
            <ixx>0.00443333</ixx>
            <ixy>0</ixy>
            <ixz>0</ixz>
            <iyy>0.00443333</iyy>
            <iyz>0</iyz>
            <izz>0.0072</izz>
          </inertia>
        </inertial>
        <collision name='base_link_collision'>
          <pose frame=''>0 0 0 0 -0 0</pose>
          <geometry>
            <mesh>
              <scale>1 1 1</scale>
              <uri>/home/akira/catkin_ws/src/bdml_ur5/src/universal_robot/ur_description/meshes/ur5/collision/base.stl</uri>
            </mesh>
          </geometry>
          <max_contacts>10</max_contacts>
          <surface>
            <contact>
              <ode/>
            </contact>
            <bounce/>
            <friction>
              <torsional>
                <ode/>
              </torsional>
              <ode/>
            </friction>
          </surface>
        </collision>
        <visual name='base_link_visual'>
          <pose frame=''>0 0 0 0 -0 0</pose>
          <geometry>
            <mesh>
              <scale>1 1 1</scale>
              <uri>/home/akira/catkin_ws/src/bdml_ur5/src/universal_robot/ur_description/meshes/ur5/visual/base.dae</uri>
            </mesh>
          </geometry>
        </visual>
        <self_collide>0</self_collide>
        <enable_wind>0</enable_wind>
        <kinematic>0</kinematic>
      </link>
      <joint name='world_joint' type='fixed'>
        <child>base_link</child>
        <parent>world</parent>
      </joint>
      <link name='shoulder_link'>
        <pose frame=''>0 0 0.089159 0 -0 0</pose>
        <inertial>
          <pose frame=''>0 0 0 0 -0 0</pose>
          <mass>3.7</mass>
          <inertia>
            <ixx>0.0102675</ixx>
            <ixy>0</ixy>
            <ixz>0</ixz>
            <iyy>0.0102675</iyy>
            <iyz>0</iyz>
            <izz>0.00666</izz>
          </inertia>
        </inertial>
        <collision name='shoulder_link_collision'>
          <pose frame=''>0 0 0 0 -0 0</pose>
          <geometry>
            <mesh>
              <scale>1 1 1</scale>
              <uri>/home/akira/catkin_ws/src/bdml_ur5/src/universal_robot/ur_description/meshes/ur5/collision/shoulder.stl</uri>
            </mesh>
          </geometry>
          <surface>
            <contact>
              <ode/>
            </contact>
            <friction>
              <ode/>
              <torsional>
                <ode/>
              </torsional>
            </friction>
            <bounce/>
          </surface>
          <max_contacts>10</max_contacts>
        </collision>
        <visual name='shoulder_link_visual'>
          <pose frame=''>0 0 0 0 -0 0</pose>
          <geometry>
            <mesh>
              <scale>1 1 1</scale>
              <uri>/home/akira/catkin_ws/src/bdml_ur5/src/universal_robot/ur_description/meshes/ur5/visual/shoulder.dae</uri>
            </mesh>
          </geometry>
          <material>
            <script>
              <uri>__default__</uri>
              <name>__default__</name>
            </script>
          </material>
        </visual>
        <gravity>1</gravity>
        <velocity_decay/>
        <self_collide>1</self_collide>
        <enable_wind>0</enable_wind>
        <kinematic>0</kinematic>
      </link>
      <joint name='shoulder_pan_joint' type='revolute'>
        <child>shoulder_link</child>
        <parent>base_link</parent>
        <axis>
          <xyz>0 0 1</xyz>
          <limit>
            <lower>-3.14159</lower>
            <upper>3.14159</upper>
            <effort>150</effort>
            <velocity>3.15</velocity>
          </limit>
          <dynamics>
            <damping>0</damping>
            <friction>0</friction>
            <spring_reference>0</spring_reference>
            <spring_stiffness>0</spring_stiffness>
          </dynamics>
          <use_parent_model_frame>1</use_parent_model_frame>
        </axis>
      </joint>
      <link name='upper_arm_link'>
        <pose frame=''>0 0.13585 0.089159 3.14159 1.57079 3.14159</pose>
        <inertial>
          <pose frame=''>0 0 0.28 0 -0 0</pose>
          <mass>8.393</mass>
          <inertia>
            <ixx>0.226891</ixx>
            <ixy>0</ixy>
            <ixz>0</ixz>
            <iyy>0.226891</iyy>
            <iyz>0</iyz>
            <izz>0.0151074</izz>
          </inertia>
        </inertial>
        <collision name='upper_arm_link_collision'>
          <pose frame=''>0 0 0 0 -0 0</pose>
          <geometry>
            <mesh>
              <scale>1 1 1</scale>
              <uri>/home/akira/catkin_ws/src/bdml_ur5/src/universal_robot/ur_description/meshes/ur5/collision/upperarm.stl</uri>
            </mesh>
          </geometry>
          <surface>
            <contact>
              <ode/>
            </contact>
            <friction>
              <ode/>
              <torsional>
                <ode/>
              </torsional>
            </friction>
            <bounce/>
          </surface>
          <max_contacts>10</max_contacts>
        </collision>
        <visual name='upper_arm_link_visual'>
          <pose frame=''>0 0 0 0 -0 0</pose>
          <geometry>
            <mesh>
              <scale>1 1 1</scale>
              <uri>/home/akira/catkin_ws/src/bdml_ur5/src/universal_robot/ur_description/meshes/ur5/visual/upperarm.dae</uri>
            </mesh>
          </geometry>
          <material>
            <script>
              <uri>__default__</uri>
              <name>__default__</name>
            </script>
          </material>
        </visual>
        <gravity>1</gravity>
        <velocity_decay/>
        <self_collide>1</self_collide>
        <enable_wind>0</enable_wind>
        <kinematic>0</kinematic>
      </link>
      <joint name='shoulder_lift_joint' type='revolute'>
        <child>upper_arm_link</child>
        <parent>shoulder_link</parent>
        <axis>
          <xyz>0 1 0</xyz>
          <limit>
            <lower>-3.14159</lower>
            <upper>3.14159</upper>
            <effort>150</effort>
            <velocity>3.15</velocity>
          </limit>
          <dynamics>
            <damping>0</damping>
            <friction>0</friction>
            <spring_reference>0</spring_reference>
            <spring_stiffness>0</spring_stiffness>
          </dynamics>
          <use_parent_model_frame>1</use_parent_model_frame>
        </axis>
      </joint>
      <link name='forearm_link'>
        <pose frame=''>0.425 0.01615 0.089159 3.14159 1.57079 3.14159</pose>
        <inertial>
          <pose frame=''>0 0 0.196125 0 -0 0</pose>
          <mass>2.275</mass>
          <inertia>
            <ixx>0.0312168</ixx>
            <ixy>0</ixy>
            <ixz>0</ixz>
            <iyy>0.0312168</iyy>
            <iyz>0</iyz>
            <izz>0.004095</izz>
          </inertia>
        </inertial>
        <collision name='forearm_link_collision'>
          <pose frame=''>0 0 0 0 -0 0</pose>
          <geometry>
            <mesh>
              <scale>1 1 1</scale>
              <uri>/home/akira/catkin_ws/src/bdml_ur5/src/universal_robot/ur_description/meshes/ur5/collision/forearm.stl</uri>
            </mesh>
          </geometry>
          <surface>
            <contact>
              <ode/>
            </contact>
            <friction>
              <ode/>
              <torsional>
                <ode/>
              </torsional>
            </friction>
            <bounce/>
          </surface>
          <max_contacts>10</max_contacts>
        </collision>
        <visual name='forearm_link_visual'>
          <pose frame=''>0 0 0 0 -0 0</pose>
          <geometry>
            <mesh>
              <scale>1 1 1</scale>
              <uri>/home/akira/catkin_ws/src/bdml_ur5/src/universal_robot/ur_description/meshes/ur5/visual/forearm.dae</uri>
            </mesh>
          </geometry>
          <material>
            <script>
              <uri>__default__</uri>
              <name>__default__</name>
            </script>
          </material>
        </visual>
        <gravity>1</gravity>
        <velocity_decay/>
        <self_collide>1</self_collide>
        <enable_wind>0</enable_wind>
        <kinematic>0</kinematic>
      </link>
      <joint name='elbow_joint' type='revolute'>
        <child>forearm_link</child>
        <parent>upper_arm_link</parent>
        <axis>
          <xyz>0 1 0</xyz>
          <limit>
            <lower>-3.14159</lower>
            <upper>3.14159</upper>
            <effort>150</effort>
            <velocity>3.15</velocity>
          </limit>
          <dynamics>
            <damping>0</damping>
            <friction>0</friction>
            <spring_reference>0</spring_reference>
            <spring_stiffness>0</spring_stiffness>
          </dynamics>
          <use_parent_model_frame>1</use_parent_model_frame>
        </axis>
      </joint>
      <link name='wrist_1_link'>
        <pose frame=''>0.81725 0.01615 0.089159 3.14159 -0 3.14159</pose>
        <inertial>
          <pose frame=''>0 0.093 0 0 -0 0</pose>
          <mass>1.219</mass>
          <inertia>
            <ixx>0.0025599</ixx>
            <ixy>0</ixy>
            <ixz>0</ixz>
            <iyy>0.0025599</iyy>
            <iyz>0</iyz>
            <izz>0.0021942</izz>
          </inertia>
        </inertial>
        <collision name='wrist_1_link_collision'>
          <pose frame=''>0 0 0 0 -0 0</pose>
          <geometry>
            <mesh>
              <scale>1 1 1</scale>
              <uri>/home/akira/catkin_ws/src/bdml_ur5/src/universal_robot/ur_description/meshes/ur5/collision/wrist1.stl</uri>
            </mesh>
          </geometry>
          <surface>
            <contact>
              <ode/>
            </contact>
            <friction>
              <ode/>
              <torsional>
                <ode/>
              </torsional>
            </friction>
            <bounce/>
          </surface>
          <max_contacts>10</max_contacts>
        </collision>
        <visual name='wrist_1_link_visual'>
          <pose frame=''>0 0 0 0 -0 0</pose>
          <geometry>
            <mesh>
              <scale>1 1 1</scale>
              <uri>/home/akira/catkin_ws/src/bdml_ur5/src/universal_robot/ur_description/meshes/ur5/visual/wrist1.dae</uri>
            </mesh>
          </geometry>
          <material>
            <script>
              <uri>__default__</uri>
              <name>__default__</name>
            </script>
          </material>
        </visual>
        <gravity>1</gravity>
        <velocity_decay/>
        <self_collide>1</self_collide>
        <enable_wind>0</enable_wind>
        <kinematic>0</kinematic>
      </link>
      <joint name='wrist_1_joint' type='revolute'>
        <child>wrist_1_link</child>
        <parent>forearm_link</parent>
        <axis>
          <xyz>0 1 0</xyz>
          <limit>
            <lower>-3.14159</lower>
            <upper>3.14159</upper>
            <effort>28</effort>
            <velocity>3.2</velocity>
          </limit>
          <dynamics>
            <damping>0</damping>
            <friction>0</friction>
            <spring_reference>0</spring_reference>
            <spring_stiffness>0</spring_stiffness>
          </dynamics>
          <use_parent_model_frame>1</use_parent_model_frame>
        </axis>
      </joint>
      <link name='wrist_2_link'>
        <pose frame=''>0.81725 0.10915 0.089159 3.14159 -0 3.14159</pose>
        <inertial>
          <pose frame=''>0 0 0.09465 0 -0 0</pose>
          <mass>1.219</mass>
          <inertia>
            <ixx>0.0025599</ixx>
            <ixy>0</ixy>
            <ixz>0</ixz>
            <iyy>0.0025599</iyy>
            <iyz>0</iyz>
            <izz>0.0021942</izz>
          </inertia>
        </inertial>
        <collision name='wrist_2_link_collision'>
          <pose frame=''>0 0 0 0 -0 0</pose>
          <geometry>
            <mesh>
              <scale>1 1 1</scale>
              <uri>/home/akira/catkin_ws/src/bdml_ur5/src/universal_robot/ur_description/meshes/ur5/collision/wrist2.stl</uri>
            </mesh>
          </geometry>
          <surface>
            <contact>
              <ode/>
            </contact>
            <friction>
              <ode/>
              <torsional>
                <ode/>
              </torsional>
            </friction>
            <bounce/>
          </surface>
          <max_contacts>10</max_contacts>
        </collision>
        <visual name='wrist_2_link_visual'>
          <pose frame=''>0 0 0 0 -0 0</pose>
          <geometry>
            <mesh>
              <scale>1 1 1</scale>
              <uri>/home/akira/catkin_ws/src/bdml_ur5/src/universal_robot/ur_description/meshes/ur5/visual/wrist2.dae</uri>
            </mesh>
          </geometry>
          <material>
            <script>
              <uri>__default__</uri>
              <name>__default__</name>
            </script>
          </material>
        </visual>
        <gravity>1</gravity>
        <velocity_decay/>
        <self_collide>1</self_collide>
        <enable_wind>0</enable_wind>
        <kinematic>0</kinematic>
      </link>
      <joint name='wrist_2_joint' type='revolute'>
        <child>wrist_2_link</child>
        <parent>wrist_1_link</parent>
        <axis>
          <xyz>0 0 -1</xyz>
          <limit>
            <lower>-3.14159</lower>
            <upper>3.14159</upper>
            <effort>28</effort>
            <velocity>3.2</velocity>
          </limit>
          <dynamics>
            <damping>0</damping>
            <friction>0</friction>
            <spring_reference>0</spring_reference>
            <spring_stiffness>0</spring_stiffness>
          </dynamics>
          <use_parent_model_frame>1</use_parent_model_frame>
        </axis>
      </joint>
      <link name='wrist_3_link'>
        <pose frame=''>0.81725 0.10915 -0.005491 3.14159 -0 3.14159</pose>
        <inertial>
          <pose frame=''>0 0.084162 0 1.5708 -0 0</pose>
          <mass>0.824851</mass>
          <inertia>
            <ixx>0.362439</ixx>
            <ixy>4.41559e-29</ixy>
            <ixz>-9.01756e-18</ixz>
            <iyy>0.362439</iyy>
            <iyz>-7.20816e-13</iyz>
            <izz>0.509693</izz>
          </inertia>
        </inertial>
        <collision name='wrist_3_link_collision'>
          <pose frame=''>0 0 0 0 -0 0</pose>
          <geometry>
            <mesh>
              <scale>1 1 1</scale>
              <uri>/home/akira/catkin_ws/src/bdml_ur5/src/universal_robot/ur_description/meshes/ur5/collision/wrist3.stl</uri>
            </mesh>
          </geometry>
          <surface>
            <contact>
              <ode/>
            </contact>
            <friction>
              <ode/>
              <torsional>
                <ode/>
              </torsional>
            </friction>
            <bounce/>
          </surface>
          <max_contacts>10</max_contacts>
        </collision>
        <collision name='wrist_3_link_fixed_joint_lump__ee_link_collision_1'>
          <pose frame=''>-0 0.0723 0 0 -0 1.5708</pose>
          <geometry>
            <box>
              <size>0.01 0.01 0.01</size>
            </box>
          </geometry>
          <surface>
            <contact>
              <ode/>
            </contact>
            <friction>
              <ode/>
              <torsional>
                <ode/>
              </torsional>
            </friction>
            <bounce/>
          </surface>
          <max_contacts>10</max_contacts>
        </collision>
        <collision name='wrist_3_link_fixed_joint_lump__simple_gripper_base_collision_2'>
          <pose frame=''>0 0.0823 0 3.14159 1.57079 -1.57079</pose>
          <geometry>
            <mesh>
              <scale>0.001 0.001 0.001</scale>
              <uri>/home/akira/catkin_ws/src/bdml_ur5/src/robotiq/robotiq_2f_model/model/meshes/2f85/collision/base.stl</uri>
            </mesh>
          </geometry>
          <surface>
            <contact>
              <ode>
                <kp>1e+08</kp>
                <kd>1</kd>
              </ode>
            </contact>
            <friction>
              <ode>
                <mu>100000</mu>
                <mu2>100000</mu2>
              </ode>
              <torsional>
                <ode/>
              </torsional>
            </friction>
            <bounce/>
          </surface>
          <max_contacts>10</max_contacts>
        </collision>
        <visual name='wrist_3_link_visual'>
          <pose frame=''>0 0 0 0 -0 0</pose>
          <geometry>
            <mesh>
              <scale>1 1 1</scale>
              <uri>/home/akira/catkin_ws/src/bdml_ur5/src/universal_robot/ur_description/meshes/ur5/visual/wrist3.dae</uri>
            </mesh>
          </geometry>
          <material>
            <script>
              <uri>__default__</uri>
              <name>__default__</name>
            </script>
          </material>
        </visual>
        <visual name='wrist_3_link_fixed_joint_lump__simple_gripper_base_visual_1'>
          <pose frame=''>0 0.0823 0 -0 -4e-06 1.5708</pose>
          <geometry>
            <mesh>
              <scale>1 1 1</scale>
              <uri>/home/akira/catkin_ws/src/bdml_ur5/src/robotiq/robotiq_2f_model/model/meshes/2f85/visual/base.dae</uri>
            </mesh>
          </geometry>
          <material>
            <script>
              <uri>__default__</uri>
              <name>__default__</name>
            </script>
          </material>
        </visual>
        <velocity_decay/>
        <velocity_decay/>
        <gravity>1</gravity>
        <velocity_decay/>
        <self_collide>1</self_collide>
        <enable_wind>0</enable_wind>
        <kinematic>0</kinematic>
      </link>
      <joint name='wrist_3_joint' type='revolute'>
        <child>wrist_3_link</child>
        <parent>wrist_2_link</parent>
        <axis>
          <xyz>0 1 0</xyz>
          <limit>
            <lower>-3.14159</lower>
            <upper>3.14159</upper>
            <effort>28</effort>
            <velocity>3.2</velocity>
          </limit>
          <dynamics>
            <damping>0</damping>
            <friction>0</friction>
            <spring_reference>0</spring_reference>
            <spring_stiffness>0</spring_stiffness>
          </dynamics>
          <use_parent_model_frame>1</use_parent_model_frame>
        </axis>
      </joint>
      <link name='simple_gripper_left_driver'>
        <pose frame=''>0.786649 0.246354 -0.005491 1.57079 1.57079 3.14159</pose>
        <inertial>
          <pose frame=''>0 0.026857 0.012462 0 -0 0</pose>
          <mass>0.0458</mass>
          <inertia>
            <ixx>0.0136135</ixx>
            <ixy>0</ixy>
            <ixz>0</ixz>
            <iyy>0.0127563</iyy>
            <iyz>-0.00111486</iyz>
            <izz>0.00618627</izz>
          </inertia>
        </inertial>
        <collision name='simple_gripper_left_driver_collision'>
          <pose frame=''>0 0 0 0 -0 0</pose>
          <geometry>
            <mesh>
              <scale>0.001 0.001 0.001</scale>
              <uri>/home/akira/catkin_ws/src/bdml_ur5/src/robotiq/robotiq_2f_model/model/meshes/2f85/collision/driver.stl</uri>
            </mesh>
          </geometry>
          <surface>
            <contact>
              <ode>
                <kp>1e+08</kp>
                <kd>1</kd>
              </ode>
            </contact>
            <friction>
              <ode>
                <mu>100000</mu>
                <mu2>100000</mu2>
              </ode>
              <torsional>
                <ode/>
              </torsional>
            </friction>
            <bounce/>
          </surface>
          <max_contacts>10</max_contacts>
        </collision>
        <visual name='simple_gripper_left_driver_visual'>
          <pose frame=''>0 0 0 0 -0 0</pose>
          <geometry>
            <mesh>
              <scale>0.001 0.001 0.001</scale>
              <uri>/home/akira/catkin_ws/src/bdml_ur5/src/robotiq/robotiq_2f_model/model/meshes/2f85/visual/driver.dae</uri>
            </mesh>
          </geometry>
          <material>
            <script>
              <uri>__default__</uri>
              <name>__default__</name>
            </script>
          </material>
        </visual>
        <visual name='simple_gripper_left_driver_fixed_joint_lump__simple_gripper_left_coupler_visual_1'>
          <pose frame=''>0 0.0315 -0.0041 0 -0 0</pose>
          <geometry>
            <mesh>
              <scale>0.001 0.001 0.001</scale>
              <uri>/home/akira/catkin_ws/src/bdml_ur5/src/robotiq/robotiq_2f_model/model/meshes/2f85/visual/coupler.dae</uri>
            </mesh>
          </geometry>
          <material>
            <script>
              <uri>__default__</uri>
              <name>__default__</name>
            </script>
          </material>
        </visual>
        <velocity_decay/>
        <gravity>1</gravity>
        <velocity_decay/>
        <self_collide>1</self_collide>
        <enable_wind>0</enable_wind>
        <kinematic>0</kinematic>
      </link>
      <joint name='simple_gripper_left_driver_joint' type='revolute'>
        <child>simple_gripper_left_driver</child>
        <parent>wrist_3_link</parent>
        <axis>
          <xyz>0 0 -1</xyz>
          <limit>
            <lower>0</lower>
            <upper>0.872664</upper>
            <effort>1000</effort>
            <velocity>1.91986</velocity>
          </limit>
          <dynamics>
            <spring_reference>0</spring_reference>
            <spring_stiffness>0</spring_stiffness>
          </dynamics>
          <use_parent_model_frame>1</use_parent_model_frame>
        </axis>
      </joint>
      <link name='simple_gripper_left_spring_link'>
        <pose frame=''>0.80525 0.25285 -0.005491 1.57079 1.57079 3.14159</pose>
        <inertial>
          <pose frame=''>0 0.018 0.018 -0.7068 0 0</pose>
          <mass>0.029951</mass>
          <inertia>
            <ixx>0.0115436</ixx>
            <ixy>0</ixy>
            <ixz>0</ixz>
            <iyy>0.0145387</iyy>
            <iyz>0</iyz>
            <izz>0.00499183</izz>
          </inertia>
        </inertial>
        <collision name='simple_gripper_left_spring_link_collision'>
          <pose frame=''>0 0 0 0 -0 0</pose>
          <geometry>
            <mesh>
              <scale>0.001 0.001 0.001</scale>
              <uri>/home/akira/catkin_ws/src/bdml_ur5/src/robotiq/robotiq_2f_model/model/meshes/2f85/collision/spring_link.stl</uri>
            </mesh>
          </geometry>
          <surface>
            <contact>
              <ode>
                <kp>1e+08</kp>
                <kd>1</kd>
              </ode>
            </contact>
            <friction>
              <ode>
                <mu>100000</mu>
                <mu2>100000</mu2>
              </ode>
              <torsional>
                <ode/>
              </torsional>
            </friction>
            <bounce/>
          </surface>
          <max_contacts>10</max_contacts>
        </collision>
        <visual name='simple_gripper_left_spring_link_visual'>
          <pose frame=''>0 0 0 0 -0 0</pose>
          <geometry>
            <mesh>
              <scale>0.001 0.001 0.001</scale>
              <uri>/home/akira/catkin_ws/src/bdml_ur5/src/robotiq/robotiq_2f_model/model/meshes/2f85/visual/spring_link.dae</uri>
            </mesh>
          </geometry>
          <material>
            <script>
              <uri>__default__</uri>
              <name>__default__</name>
            </script>
          </material>
        </visual>
        <gravity>1</gravity>
        <velocity_decay/>
        <self_collide>1</self_collide>
        <enable_wind>0</enable_wind>
        <kinematic>0</kinematic>
      </link>
      <joint name='simple_gripper_left_spring_link_joint' type='revolute'>
        <child>simple_gripper_left_spring_link</child>
        <parent>wrist_3_link</parent>
        <axis>
          <xyz>0 0 -1</xyz>
          <limit>
            <lower>-2.96706</lower>
            <upper>2.96706</upper>
            <effort>17600</effort>
            <velocity>1.91986</velocity>
          </limit>
          <dynamics>
            <spring_reference>0</spring_reference>
            <spring_stiffness>0</spring_stiffness>
          </dynamics>
          <use_parent_model_frame>1</use_parent_model_frame>
        </axis>
      </joint>
      <link name='simple_gripper_left_follower'>
        <pose frame=''>0.76825 0.29585 -0.005491 1.57079 1.57079 3.14159</pose>
        <inertial>
          <pose frame=''>0 0.018 -0.0065 0 -0 0</pose>
          <mass>0.019555</mass>
          <inertia>
            <ixx>0.0031904</ixx>
            <ixy>0</ixy>
            <ixz>0</ixz>
            <iyy>0.00360377</iyy>
            <iyz>0</iyz>
            <izz>0.000890293</izz>
          </inertia>
        </inertial>
        <collision name='simple_gripper_left_follower_collision'>
          <pose frame=''>0 0.018 -0.0065 0 -0 0</pose>
          <geometry>
            <mesh>
              <scale>0.001 0.001 0.001</scale>
              <uri>/home/akira/catkin_ws/src/bdml_ur5/src/robotiq/robotiq_2f_model/model/meshes/2f85/collision/follower.stl</uri>
            </mesh>
          </geometry>
          <surface>
            <contact>
              <ode>
                <kp>1e+08</kp>
                <kd>1</kd>
              </ode>
            </contact>
            <friction>
              <ode>
                <mu>100000</mu>
                <mu2>100000</mu2>
              </ode>
              <torsional>
                <ode/>
              </torsional>
            </friction>
            <bounce/>
          </surface>
          <max_contacts>10</max_contacts>
        </collision>
        <collision name='simple_gripper_left_follower_fixed_joint_lump__simple_gripper_left_pad_collision_1'>
          <pose frame=''>0 0.018 -0.0065 0 -0 0</pose>
          <geometry>
            <mesh>
              <scale>0.001 0.001 0.001</scale>
              <uri>/home/akira/catkin_ws/src/bdml_ur5/src/robotiq/robotiq_2f_model/model/meshes/2f85/collision/pad.stl</uri>
            </mesh>
          </geometry>
          <surface>
            <contact>
              <ode>
                <kp>1e+08</kp>
                <kd>1</kd>
              </ode>
            </contact>
            <friction>
              <ode>
                <mu>100000</mu>
                <mu2>100000</mu2>
              </ode>
              <torsional>
                <ode/>
              </torsional>
            </friction>
            <bounce/>
          </surface>
          <max_contacts>10</max_contacts>
        </collision>
        <visual name='simple_gripper_left_follower_visual'>
          <pose frame=''>0 0.018 -0.0065 0 -0 0</pose>
          <geometry>
            <mesh>
              <scale>0.001 0.001 0.001</scale>
              <uri>/home/akira/catkin_ws/src/bdml_ur5/src/robotiq/robotiq_2f_model/model/meshes/2f85/visual/follower.dae</uri>
            </mesh>
          </geometry>
          <material>
            <script>
              <uri>__default__</uri>
              <name>__default__</name>
            </script>
          </material>
        </visual>
        <visual name='simple_gripper_left_follower_fixed_joint_lump__simple_gripper_left_pad_visual_1'>
          <pose frame=''>0 0.018 -0.0065 0 -0 0</pose>
          <geometry>
            <mesh>
              <scale>0.001 0.001 0.001</scale>
              <uri>/home/akira/catkin_ws/src/bdml_ur5/src/robotiq/robotiq_2f_model/model/meshes/2f85/visual/pad.dae</uri>
            </mesh>
          </geometry>
          <material>
            <script>
              <uri>__default__</uri>
              <name>__default__</name>
            </script>
          </material>
        </visual>
        <velocity_decay/>
        <gravity>1</gravity>
        <velocity_decay/>
        <self_collide>1</self_collide>
        <enable_wind>0</enable_wind>
        <kinematic>0</kinematic>
      </link>
      <joint name='simple_gripper_left_follower_joint' type='revolute'>
        <child>simple_gripper_left_follower</child>
        <parent>simple_gripper_left_spring_link</parent>
        <axis>
          <xyz>0 0 -1</xyz>
          <limit>
            <lower>-2.96706</lower>
            <upper>2.96706</upper>
            <effort>1000</effort>
            <velocity>1.91986</velocity>
          </limit>
          <dynamics>
            <spring_reference>0</spring_reference>
            <spring_stiffness>0</spring_stiffness>
          </dynamics>
          <use_parent_model_frame>1</use_parent_model_frame>
        </axis>
      </joint>
      <link name='simple_gripper_right_driver'>
        <pose frame=''>0.847851 0.246354 -0.005491 1.57079 -1.57079 3.14159</pose>
        <inertial>
          <pose frame=''>0 0.026857 0.012462 0 -0 0</pose>
          <mass>0.0458</mass>
          <inertia>
            <ixx>0.0136135</ixx>
            <ixy>0</ixy>
            <ixz>0</ixz>
            <iyy>0.0127563</iyy>
            <iyz>-0.00111486</iyz>
            <izz>0.00618627</izz>
          </inertia>
        </inertial>
        <collision name='simple_gripper_right_driver_collision'>
          <pose frame=''>0 0 0 0 -0 0</pose>
          <geometry>
            <mesh>
              <scale>0.001 0.001 0.001</scale>
              <uri>/home/akira/catkin_ws/src/bdml_ur5/src/robotiq/robotiq_2f_model/model/meshes/2f85/collision/driver.stl</uri>
            </mesh>
          </geometry>
          <surface>
            <contact>
              <ode>
                <kp>1e+08</kp>
                <kd>1</kd>
              </ode>
            </contact>
            <friction>
              <ode>
                <mu>100000</mu>
                <mu2>100000</mu2>
              </ode>
              <torsional>
                <ode/>
              </torsional>
            </friction>
            <bounce/>
          </surface>
          <max_contacts>10</max_contacts>
        </collision>
        <visual name='simple_gripper_right_driver_visual'>
          <pose frame=''>0 0 0 0 -0 0</pose>
          <geometry>
            <mesh>
              <scale>0.001 0.001 0.001</scale>
              <uri>/home/akira/catkin_ws/src/bdml_ur5/src/robotiq/robotiq_2f_model/model/meshes/2f85/visual/driver.dae</uri>
            </mesh>
          </geometry>
          <material>
            <script>
              <uri>__default__</uri>
              <name>__default__</name>
            </script>
          </material>
        </visual>
        <visual name='simple_gripper_right_driver_fixed_joint_lump__simple_gripper_right_coupler_visual_1'>
          <pose frame=''>0 0.0315 -0.0041 0 -0 0</pose>
          <geometry>
            <mesh>
              <scale>0.001 0.001 0.001</scale>
              <uri>/home/akira/catkin_ws/src/bdml_ur5/src/robotiq/robotiq_2f_model/model/meshes/2f85/visual/coupler.dae</uri>
            </mesh>
          </geometry>
          <material>
            <script>
              <uri>__default__</uri>
              <name>__default__</name>
            </script>
          </material>
        </visual>
        <velocity_decay/>
        <gravity>1</gravity>
        <velocity_decay/>
        <self_collide>1</self_collide>
        <enable_wind>0</enable_wind>
        <kinematic>0</kinematic>
      </link>
      <joint name='simple_gripper_right_driver_joint' type='revolute'>
        <child>simple_gripper_right_driver</child>
        <parent>wrist_3_link</parent>
        <axis>
          <xyz>-0 0 1</xyz>
          <limit>
            <lower>0</lower>
            <upper>0.872664</upper>
            <effort>1000</effort>
            <velocity>1.91986</velocity>
          </limit>
          <dynamics>
            <spring_reference>0</spring_reference>
            <spring_stiffness>0</spring_stiffness>
          </dynamics>
          <use_parent_model_frame>1</use_parent_model_frame>
        </axis>
      </joint>
      <link name='simple_gripper_right_spring_link'>
        <pose frame=''>0.82925 0.25285 -0.005491 1.57079 -1.57079 3.14159</pose>
        <inertial>
          <pose frame=''>0 0.018 0.018 -0.7068 0 0</pose>
          <mass>0.029951</mass>
          <inertia>
            <ixx>0.0115436</ixx>
            <ixy>0</ixy>
            <ixz>0</ixz>
            <iyy>0.0145387</iyy>
            <iyz>0</iyz>
            <izz>0.00499183</izz>
          </inertia>
        </inertial>
        <collision name='simple_gripper_right_spring_link_collision'>
          <pose frame=''>0 0 0 0 -0 0</pose>
          <geometry>
            <mesh>
              <scale>0.001 0.001 0.001</scale>
              <uri>/home/akira/catkin_ws/src/bdml_ur5/src/robotiq/robotiq_2f_model/model/meshes/2f85/collision/spring_link.stl</uri>
            </mesh>
          </geometry>
          <surface>
            <contact>
              <ode>
                <kp>1e+08</kp>
                <kd>1</kd>
              </ode>
            </contact>
            <friction>
              <ode>
                <mu>100000</mu>
                <mu2>100000</mu2>
              </ode>
              <torsional>
                <ode/>
              </torsional>
            </friction>
            <bounce/>
          </surface>
          <max_contacts>10</max_contacts>
        </collision>
        <visual name='simple_gripper_right_spring_link_visual'>
          <pose frame=''>0 0 0 0 -0 0</pose>
          <geometry>
            <mesh>
              <scale>0.001 0.001 0.001</scale>
              <uri>/home/akira/catkin_ws/src/bdml_ur5/src/robotiq/robotiq_2f_model/model/meshes/2f85/visual/spring_link.dae</uri>
            </mesh>
          </geometry>
          <material>
            <script>
              <uri>__default__</uri>
              <name>__default__</name>
            </script>
          </material>
        </visual>
        <gravity>1</gravity>
        <velocity_decay/>
        <self_collide>1</self_collide>
        <enable_wind>0</enable_wind>
        <kinematic>0</kinematic>
      </link>
      <joint name='simple_gripper_right_spring_link_joint' type='revolute'>
        <child>simple_gripper_right_spring_link</child>
        <parent>wrist_3_link</parent>
        <axis>
          <xyz>-0 0 1</xyz>
          <limit>
            <lower>-2.96706</lower>
            <upper>2.96706</upper>
            <effort>1000</effort>
            <velocity>1.91986</velocity>
          </limit>
          <dynamics>
            <spring_reference>0</spring_reference>
            <spring_stiffness>0</spring_stiffness>
          </dynamics>
          <use_parent_model_frame>1</use_parent_model_frame>
        </axis>
      </joint>
      <link name='simple_gripper_right_follower'>
        <pose frame=''>0.86625 0.29585 -0.005491 1.57079 -1.57079 3.14159</pose>
        <inertial>
          <pose frame=''>0 0.018 -0.0065 0 -0 0</pose>
          <mass>0.019555</mass>
          <inertia>
            <ixx>0.0031904</ixx>
            <ixy>0</ixy>
            <ixz>0</ixz>
            <iyy>0.00360377</iyy>
            <iyz>0</iyz>
            <izz>0.000890293</izz>
          </inertia>
        </inertial>
        <collision name='simple_gripper_right_follower_collision'>
          <pose frame=''>0 0.018 -0.0065 0 -0 0</pose>
          <geometry>
            <mesh>
              <scale>0.001 0.001 0.001</scale>
              <uri>/home/akira/catkin_ws/src/bdml_ur5/src/robotiq/robotiq_2f_model/model/meshes/2f85/collision/follower.stl</uri>
            </mesh>
          </geometry>
          <surface>
            <contact>
              <ode>
                <kp>1e+08</kp>
                <kd>1</kd>
              </ode>
            </contact>
            <friction>
              <ode>
                <mu>100000</mu>
                <mu2>100000</mu2>
              </ode>
              <torsional>
                <ode/>
              </torsional>
            </friction>
            <bounce/>
          </surface>
          <max_contacts>10</max_contacts>
        </collision>
        <collision name='simple_gripper_right_follower_fixed_joint_lump__simple_gripper_right_pad_collision_1'>
          <pose frame=''>0 0.018 -0.0065 0 -0 0</pose>
          <geometry>
            <mesh>
              <scale>0.001 0.001 0.001</scale>
              <uri>/home/akira/catkin_ws/src/bdml_ur5/src/robotiq/robotiq_2f_model/model/meshes/2f85/collision/pad.stl</uri>
            </mesh>
          </geometry>
          <surface>
            <contact>
              <ode>
                <kp>1e+08</kp>
                <kd>1</kd>
              </ode>
            </contact>
            <friction>
              <ode>
                <mu>100000</mu>
                <mu2>100000</mu2>
              </ode>
              <torsional>
                <ode/>
              </torsional>
            </friction>
            <bounce/>
          </surface>
          <max_contacts>10</max_contacts>
        </collision>
        <visual name='simple_gripper_right_follower_visual'>
          <pose frame=''>0 0.018 -0.0065 0 -0 0</pose>
          <geometry>
            <mesh>
              <scale>0.001 0.001 0.001</scale>
              <uri>/home/akira/catkin_ws/src/bdml_ur5/src/robotiq/robotiq_2f_model/model/meshes/2f85/visual/follower.dae</uri>
            </mesh>
          </geometry>
          <material>
            <script>
              <uri>__default__</uri>
              <name>__default__</name>
            </script>
          </material>
        </visual>
        <visual name='simple_gripper_right_follower_fixed_joint_lump__simple_gripper_right_pad_visual_1'>
          <pose frame=''>0 0.018 -0.0065 0 -0 0</pose>
          <geometry>
            <mesh>
              <scale>0.001 0.001 0.001</scale>
              <uri>/home/akira/catkin_ws/src/bdml_ur5/src/robotiq/robotiq_2f_model/model/meshes/2f85/visual/pad.dae</uri>
            </mesh>
          </geometry>
          <material>
            <script>
              <uri>__default__</uri>
              <name>__default__</name>
            </script>
          </material>
        </visual>
        <velocity_decay/>
        <gravity>1</gravity>
        <velocity_decay/>
        <self_collide>1</self_collide>
        <enable_wind>0</enable_wind>
        <kinematic>0</kinematic>
      </link>
      <joint name='simple_gripper_right_follower_joint' type='revolute'>
        <child>simple_gripper_right_follower</child>
        <parent>simple_gripper_right_spring_link</parent>
        <axis>
          <xyz>-0 0 1</xyz>
          <limit>
            <lower>-2.96706</lower>
            <upper>2.96706</upper>
            <effort>1000</effort>
            <velocity>1.91986</velocity>
          </limit>
          <dynamics>
            <spring_reference>0</spring_reference>
            <spring_stiffness>0</spring_stiffness>
          </dynamics>
          <use_parent_model_frame>1</use_parent_model_frame>
        </axis>
      </joint>
      <plugin name='ros_control' filename='libgazebo_ros_control.so'>
        <robotNamespace>/</robotNamespace>
      </plugin>
      <static>0</static>
      <pose frame=''>0 0 0.1 0 -0 0</pose>
    </model>
    <model name='drc_practice_weighted_door'>
      <link name='frame'>
        <pose frame=''>0.06 -0.0005 0 0 -0 0</pose>
        <inertial>
          <pose frame=''>-0.025145 -0.03429 1.0541 0 -0 0</pose>
          <mass>19</mass>
          <inertia>
            <ixx>7.04458</ixx>
            <ixy>0</ixy>
            <ixz>0</ixz>
            <iyy>7.04114</iyy>
            <iyz>0</iyz>
            <izz>0.0114511</izz>
          </inertia>
        </inertial>
        <collision name='collision_2'>
          <pose frame=''>-0.025145 -0.03429 1.0541 0 -0 0</pose>
          <geometry>
            <box>
              <size>0.05029 0.06858 2.1082</size>
            </box>
          </geometry>
          <max_contacts>10</max_contacts>
          <surface>
            <contact>
              <ode/>
            </contact>
            <bounce/>
            <friction>
              <torsional>
                <ode/>
              </torsional>
              <ode/>
            </friction>
          </surface>
        </collision>
        <visual name='visual'>
          <pose frame=''>-0.025145 -0.03429 1.0541 0 -0 0</pose>
          <geometry>
            <box>
              <size>0.05029 0.06858 2.1082</size>
            </box>
          </geometry>
          <material>
            <script>
              <uri>file://media/materials/scripts/gazebo.material</uri>
              <name>Gazebo/White</name>
            </script>
          </material>
        </visual>
        <self_collide>0</self_collide>
        <enable_wind>0</enable_wind>
        <kinematic>0</kinematic>
      </link>
      <link name='door'>
        <pose frame=''>-0 0 2.04 3.14159 -0 0</pose>
        <inertial>
          <mass>41.3256</mass>
          <pose frame=''>0.4569 0.0349 1.016 0 -0 0</pose>
          <inertia>
            <ixx>14.2263</ixx>
            <ixy>0</ixy>
            <ixz>0</ixz>
            <iyy>17.099</iyy>
            <iyz>0</iyz>
            <izz>2.88626</izz>
          </inertia>
        </inertial>
        <collision name='collision'>
          <pose frame=''>0.4569 0.0349 1.016 0 -0 0</pose>
          <geometry>
            <box>
              <size>0.9144 0.04445 2.032</size>
            </box>
          </geometry>
          <max_contacts>10</max_contacts>
          <surface>
            <contact>
              <ode/>
            </contact>
            <bounce/>
            <friction>
              <torsional>
                <ode/>
              </torsional>
              <ode/>
            </friction>
          </surface>
        </collision>
        <visual name='visual'>
          <pose frame=''>0 -0.06858 0 0 -0 0</pose>
          <geometry>
            <mesh>
              <uri>model://hinged_door/meshes/door.dae</uri>
            </mesh>
          </geometry>
        </visual>
        <self_collide>0</self_collide>
        <enable_wind>0</enable_wind>
        <kinematic>0</kinematic>
      </link>
      <link name='handles'>
        <pose frame=''>0.8144 -0.07 1.05 0 -0 3.14159</pose>
        <inertial>
          <pose frame=''>0 -0.035 0 0 -0 0</pose>
          <mass>2</mass>
          <inertia>
            <ixx>0.0110115</ixx>
            <ixy>-0</ixy>
            <ixz>-0.00647057</ixz>
            <iyy>0.0190181</iyy>
            <iyz>0</iyz>
            <izz>0.00824372</izz>
          </inertia>
        </inertial>
        <collision name='handle1_collision'>
          <pose frame=''>0.015 -0.015 0 -1.57 0 0</pose>
          <geometry>
            <mesh>
              <uri>model://door_handle/meshes/handle.dae</uri>
            </mesh>
          </geometry>
          <max_contacts>10</max_contacts>
          <surface>
            <contact>
              <ode/>
            </contact>
            <bounce/>
            <friction>
              <torsional>
                <ode/>
              </torsional>
              <ode/>
            </friction>
          </surface>
        </collision>
        <visual name='handle1_visual'>
          <pose frame=''>0.015 -0.015 0 -1.57 0 0</pose>
          <geometry>
            <mesh>
              <uri>model://door_handle/meshes/handle.dae</uri>
            </mesh>
          </geometry>
        </visual>
        <collision name='handle2_collision'>
          <pose frame=''>0.015 -0.055 0 1.57 -0 0</pose>
          <geometry>
            <mesh>
              <uri>model://door_handle/meshes/handle.dae</uri>
            </mesh>
          </geometry>
          <max_contacts>10</max_contacts>
          <surface>
            <contact>
              <ode/>
            </contact>
            <bounce/>
            <friction>
              <torsional>
                <ode/>
              </torsional>
              <ode/>
            </friction>
          </surface>
        </collision>
        <visual name='handle2_visual'>
          <pose frame=''>0.015 -0.055 0 1.57 -0 0</pose>
          <geometry>
            <mesh>
              <uri>model://door_handle/meshes/handle.dae</uri>
            </mesh>
          </geometry>
        </visual>
        <self_collide>0</self_collide>
        <enable_wind>0</enable_wind>
        <kinematic>0</kinematic>
      </link>
      <joint name='handle' type='revolute'>
        <parent>door</parent>
        <child>handles</child>
        <pose frame=''>0.015 0 0 0 -0 0</pose>
        <axis>
          <xyz>0 1 0</xyz>
          <limit>
            <lower>-1.58</lower>
            <upper>0</upper>
          </limit>
          <dynamics>
            <damping>1</damping>
            <friction>10</friction>
            <spring_reference>0</spring_reference>
            <spring_stiffness>0</spring_stiffness>
          </dynamics>
          <use_parent_model_frame>1</use_parent_model_frame>
          <use_parent_model_frame>1</use_parent_model_frame>
        </axis>
        <physics>
          <ode>
            <cfm_damping>1</cfm_damping>
            <limit>
              <cfm>0</cfm>
              <erp>0.2</erp>
            </limit>
          </ode>
        </physics>
      </joint>
      <joint name='hinge' type='revolute'>
        <parent>frame</parent>
        <child>door</child>
        <axis>
          <xyz>0 0 1</xyz>
          <limit>
            <lower>-1.58</lower>
            <upper>0</upper>
          </limit>
          <dynamics>
            <damping>15.5365</damping>
            <friction>15.5365</friction>
            <spring_reference>0</spring_reference>
            <spring_stiffness>0</spring_stiffness>
          </dynamics>
          <use_parent_model_frame>1</use_parent_model_frame>
          <use_parent_model_frame>1</use_parent_model_frame>
        </axis>
        <physics>
          <ode>
            <cfm_damping>1</cfm_damping>
            <limit>
              <cfm>0</cfm>
              <erp>0.2</erp>
            </limit>
          </ode>
        </physics>
      </joint>
      <joint name='world_joint' type='revolute'>
        <child>frame</child>
        <parent>world</parent>
        <axis>
          <limit>
            <lower>0</lower>
            <upper>0</upper>
          </limit>
          <xyz>0 1 0</xyz>
          <dynamics>
            <damping>1</damping>
            <spring_reference>0</spring_reference>
            <spring_stiffness>0</spring_stiffness>
          </dynamics>
          <use_parent_model_frame>1</use_parent_model_frame>
          <use_parent_model_frame>1</use_parent_model_frame>
        </axis>
        <physics>
          <ode>
            <cfm_damping>1</cfm_damping>
            <limit>
              <cfm>0</cfm>
              <erp>0.2</erp>
            </limit>
          </ode>
        </physics>
      </joint>
      <pose frame=''>-0.368858 1.03339 0 0 -0 0</pose>
    </model>
    <model name='table'>
      <static>1</static>
      <link name='link'>
        <collision name='surface'>
          <pose frame=''>0 0 1 0 -0 0</pose>
          <geometry>
            <box>
              <size>1.5 0.8 0.03</size>
            </box>
          </geometry>
          <surface>
            <friction>
              <ode>
                <mu>0.6</mu>
                <mu2>0.6</mu2>
              </ode>
              <torsional>
                <ode/>
              </torsional>
            </friction>
            <contact>
              <ode/>
            </contact>
            <bounce/>
          </surface>
          <max_contacts>10</max_contacts>
        </collision>
        <visual name='visual1'>
          <pose frame=''>0 0 1 0 -0 0</pose>
          <geometry>
            <box>
              <size>1.5 0.8 0.03</size>
            </box>
          </geometry>
          <material>
            <script>
              <uri>file://media/materials/scripts/gazebo.material</uri>
              <name>Gazebo/Wood</name>
            </script>
          </material>
        </visual>
        <collision name='front_left_leg'>
          <pose frame=''>0.68 0.38 0.5 0 -0 0</pose>
          <geometry>
            <cylinder>
              <radius>0.02</radius>
              <length>1</length>
            </cylinder>
          </geometry>
          <max_contacts>10</max_contacts>
          <surface>
            <contact>
              <ode/>
            </contact>
            <bounce/>
            <friction>
              <torsional>
                <ode/>
              </torsional>
              <ode/>
            </friction>
          </surface>
        </collision>
        <visual name='front_left_leg'>
          <pose frame=''>0.68 0.38 0.5 0 -0 0</pose>
          <geometry>
            <cylinder>
              <radius>0.02</radius>
              <length>1</length>
            </cylinder>
          </geometry>
          <material>
            <script>
              <uri>file://media/materials/scripts/gazebo.material</uri>
              <name>Gazebo/Grey</name>
            </script>
          </material>
        </visual>
        <collision name='front_right_leg'>
          <pose frame=''>0.68 -0.38 0.5 0 -0 0</pose>
          <geometry>
            <cylinder>
              <radius>0.02</radius>
              <length>1</length>
            </cylinder>
          </geometry>
          <max_contacts>10</max_contacts>
          <surface>
            <contact>
              <ode/>
            </contact>
            <bounce/>
            <friction>
              <torsional>
                <ode/>
              </torsional>
              <ode/>
            </friction>
          </surface>
        </collision>
        <visual name='front_right_leg'>
          <pose frame=''>0.68 -0.38 0.5 0 -0 0</pose>
          <geometry>
            <cylinder>
              <radius>0.02</radius>
              <length>1</length>
            </cylinder>
          </geometry>
          <material>
            <script>
              <uri>file://media/materials/scripts/gazebo.material</uri>
              <name>Gazebo/Grey</name>
            </script>
          </material>
        </visual>
        <collision name='back_right_leg'>
          <pose frame=''>-0.68 -0.38 0.5 0 -0 0</pose>
          <geometry>
            <cylinder>
              <radius>0.02</radius>
              <length>1</length>
            </cylinder>
          </geometry>
          <max_contacts>10</max_contacts>
          <surface>
            <contact>
              <ode/>
            </contact>
            <bounce/>
            <friction>
              <torsional>
                <ode/>
              </torsional>
              <ode/>
            </friction>
          </surface>
        </collision>
        <visual name='back_right_leg'>
          <pose frame=''>-0.68 -0.38 0.5 0 -0 0</pose>
          <geometry>
            <cylinder>
              <radius>0.02</radius>
              <length>1</length>
            </cylinder>
          </geometry>
          <material>
            <script>
              <uri>file://media/materials/scripts/gazebo.material</uri>
              <name>Gazebo/Grey</name>
            </script>
          </material>
        </visual>
        <collision name='back_left_leg'>
          <pose frame=''>-0.68 0.38 0.5 0 -0 0</pose>
          <geometry>
            <cylinder>
              <radius>0.02</radius>
              <length>1</length>
            </cylinder>
          </geometry>
          <max_contacts>10</max_contacts>
          <surface>
            <contact>
              <ode/>
            </contact>
            <bounce/>
            <friction>
              <torsional>
                <ode/>
              </torsional>
              <ode/>
            </friction>
          </surface>
        </collision>
        <visual name='back_left_leg'>
          <pose frame=''>-0.68 0.38 0.5 0 -0 0</pose>
          <geometry>
            <cylinder>
              <radius>0.02</radius>
              <length>1</length>
            </cylinder>
          </geometry>
          <material>
            <script>
              <uri>file://media/materials/scripts/gazebo.material</uri>
              <name>Gazebo/Grey</name>
            </script>
          </material>
        </visual>
        <self_collide>0</self_collide>
        <enable_wind>0</enable_wind>
        <kinematic>0</kinematic>
      </link>
      <pose frame=''>1.55819 1.24706 0 0 -0 0</pose>
    </model>
    <model name='wood_cube_5cm'>
      <link name='link'>
        <pose frame=''>0 0 0.025 0 -0 0</pose>
        <inertial>
          <mass>0.0565</mass>
          <inertia>
            <ixx>2.35417e-05</ixx>
            <ixy>0</ixy>
            <ixz>0</ixz>
            <iyy>2.35417e-05</iyy>
            <iyz>0</iyz>
            <izz>2.35417e-05</izz>
          </inertia>
        </inertial>
        <collision name='collision'>
          <geometry>
            <box>
              <size>0.05 0.05 0.05</size>
            </box>
          </geometry>
          <surface>
            <contact>
              <poissons_ratio>0.347</poissons_ratio>
              <elastic_modulus>8.8e+09</elastic_modulus>
              <ode>
                <kp>100000</kp>
                <kd>1</kd>
                <max_vel>1</max_vel>
                <min_depth>0.001</min_depth>
              </ode>
            </contact>
            <friction>
              <torsional>
                <coefficient>1</coefficient>
                <use_patch_radius>0</use_patch_radius>
                <surface_radius>0.05</surface_radius>
                <ode/>
              </torsional>
              <ode/>
            </friction>
            <bounce/>
          </surface>
          <max_contacts>10</max_contacts>
        </collision>
        <visual name='visual'>
          <geometry>
            <box>
              <size>0.05 0.05 0.05</size>
            </box>
          </geometry>
          <material>
            <script>
              <uri>file://media/materials/scripts/gazebo.material</uri>
              <name>Gazebo/Wood</name>
            </script>
          </material>
        </visual>
        <self_collide>0</self_collide>
        <enable_wind>0</enable_wind>
        <kinematic>0</kinematic>
      </link>
      <pose frame=''>0.776594 0.380293 0 0 -0 0</pose>
    </model>
    <state world_name='default'>
      <sim_time>757 481000000</sim_time>
      <real_time>762 359035588</real_time>
      <wall_time>1590795411 68967742</wall_time>
      <iterations>757481</iterations>
      <model name='drc_practice_weighted_door'>
        <pose frame=''>-0.368858 1.03339 0 0 -0 0</pose>
        <scale>1 1 1</scale>
        <link name='door'>
          <pose frame=''>-0.368858 1.03339 2.04 3.14159 0 -3e-06</pose>
          <velocity>0.000138 -3e-06 3e-06 0 8.1e-05 7.1e-05</velocity>
          <acceleration>0.100785 0.004734 -0.063308 0.000502 0.150103 0.023424</acceleration>
          <wrench>4.16499 0.195643 -2.61625 0 -0 0</wrench>
        </link>
        <link name='frame'>
          <pose frame=''>-0.308858 1.03289 0 0 -0 0</pose>
          <velocity>-1.6e-05 9e-06 -0 0 8.3e-05 7.7e-05</velocity>
          <acceleration>0.135244 0.013263 0.003533 7.7e-05 0.154113 0.156441</acceleration>
          <wrench>2.56963 0.252 0.067131 0 -0 0</wrench>
        </link>
        <link name='handles'>
          <pose frame=''>0.442272 0.963387 1.05935 -2e-06 0.672937 3.14159</pose>
          <velocity>6.3e-05 5.4e-05 -6.3e-05 5e-06 8.1e-05 6.9e-05</velocity>
          <acceleration>0.103907 0.012947 -0.116623 -0.009563 0.150565 0.008008</acceleration>
          <wrench>0.207815 0.025894 -0.233247 0 -0 0</wrench>
        </link>
      </model>
      <model name='ground_plane'>
        <pose frame=''>0 0 0 0 -0 0</pose>
        <scale>1 1 1</scale>
        <link name='link'>
          <pose frame=''>0 0 0 0 -0 0</pose>
          <velocity>0 0 0 0 -0 0</velocity>
          <acceleration>0 0 0 0 -0 0</acceleration>
          <wrench>0 0 0 0 -0 0</wrench>
        </link>
      </model>
      <model name='robot'>
        <pose frame=''>0 0 0.1 3.4e-05 -0.000163 0</pose>
        <scale>1 1 1</scale>
        <link name='base_link'>
          <pose frame=''>0 0 0.1 3.4e-05 -0.000163 0</pose>
          <velocity>-1e-06 -0 0 6.6e-05 7e-06 -3e-06</velocity>
          <acceleration>-0.001497 -0.000383 0.00069 0.132172 0.014056 -0.006724</acceleration>
          <wrench>-0.005988 -0.001534 0.00276 0 -0 0</wrench>
        </link>
        <link name='forearm_link'>
          <pose frame=''>0.424944 0.015989 0.182816 -3.1343 1.55596 -3.13467</pose>
          <velocity>-0.000247 -7.6e-05 -0.019727 -0.000269 0.046164 -0.000165</velocity>
          <acceleration>0.09055 -0.064412 0.044041 1.92674 -0.019936 0.045281</acceleration>
          <wrench>0.206002 -0.146537 0.100193 0 -0 0</wrench>
        </link>
        <link name='shoulder_link'>
          <pose frame=''>-1.5e-05 -3e-06 0.189159 -6.4e-05 0.00031 -0.000367</pose>
          <velocity>1.9e-05 -1e-06 -0 -0.000147 7.3e-05 -0.000114</velocity>
          <acceleration>0.038892 -0.002503 -0.000844 -0.294524 0.145398 0.006772</acceleration>
          <wrench>0.143901 -0.009262 -0.003124 0 -0 0</wrench>
        </link>
        <link name='simple_gripper_left_driver'>
          <pose frame=''>0.7852 0.24605 0.082795 1.58268 1.55483 -3.13035</pose>
          <velocity>-0.005278 -0.000195 -0.036223 4.9e-05 0.050129 0.001936</velocity>
          <acceleration>-0.0047 -0.155136 0.055907 0.041903 -0.257731 0.635118</acceleration>
          <wrench>-0.000215 -0.007105 0.002561 0 -0 0</wrench>
        </link>
        <link name='simple_gripper_left_follower'>
          <pose frame=''>0.766834 0.295558 0.083079 1.58267 1.55483 -3.13035</pose>
          <velocity>-0.00536 -0.000231 -0.0353 4.9e-05 0.05013 0.001934</velocity>
          <acceleration>-0.046654 -0.168564 0.056666 0.016814 0.006333 0.389732</acceleration>
          <wrench>-0.000912 -0.003296 0.001108 0 -0 0</wrench>
        </link>
        <link name='simple_gripper_left_spring_link'>
          <pose frame=''>0.803802 0.252534 0.082497 1.58268 1.55483 -3.13035</pose>
          <velocity>-0.005303 -0.000159 -0.037155 5e-05 0.05013 0.001939</velocity>
          <acceleration>-0.016036 -0.117008 0.056566 0.446755 -0.953982 1.0867</acceleration>
          <wrench>-0.00048 -0.003505 0.001694 0 -0 0</wrench>
        </link>
        <link name='simple_gripper_right_driver'>
          <pose frame=''>0.846394 0.246011 0.081819 -1.58269 -1.55485 0.011253</pose>
          <velocity>-0.005328 -7.7e-05 -0.039291 5e-05 0.050129 0.001953</velocity>
          <acceleration>-0.006259 0.00638 0.055761 0.398555 -0.196079 2.90871</acceleration>
          <wrench>-0.000287 0.000292 0.002554 0 -0 0</wrench>
        </link>
        <link name='simple_gripper_right_follower'>
          <pose frame=''>0.864822 0.295495 0.081515 -1.5827 -1.55485 0.011256</pose>
          <velocity>-0.005432 -4.1e-05 -0.040212 5.1e-05 0.050129 0.00195</velocity>
          <acceleration>-0.035492 0.019852 0.057028 0.019581 -0.00088 0.39183</acceleration>
          <wrench>-0.000694 0.000388 0.001115 0 -0 0</wrench>
        </link>
        <link name='simple_gripper_right_spring_link'>
          <pose frame=''>0.827799 0.252519 0.082114 -1.58269 -1.55485 0.01125</pose>
          <velocity>-0.005327 -0.000113 -0.038358 4.9e-05 0.050128 0.001933</velocity>
          <acceleration>-0.025619 -0.032611 0.055908 -0.410661 -0.956164 1.0976</acceleration>
          <wrench>-0.000767 -0.000977 0.001674 0 -0 0</wrench>
        </link>
        <link name='upper_arm_link'>
          <pose frame=''>3.5e-05 0.135847 0.189138 -3.13269 1.5559 -3.13306</pose>
          <velocity>6.7e-05 2e-06 -2.9e-05 -0.000221 0.046455 -0.000175</velocity>
          <acceleration>0.101915 -0.027601 -0.050317 -0.865383 -0.024748 0.092522</acceleration>
          <wrench>0.85537 -0.231656 -0.42231 0 -0 0</wrench>
        </link>
        <link name='wrist_1_link'>
          <pose frame=''>0.81715 0.015844 0.176987 -3.14146 -0.015559 3.14122</pose>
          <velocity>-0.000514 -0.000142 -0.037809 -0.000222 0.048522 -0.000138</velocity>
          <acceleration>0.096598 -0.082904 0.051259 -0.479687 0.049388 -0.030299</acceleration>
          <wrench>0.117752 -0.10106 0.062485 0 -0 0</wrench>
        </link>
        <link name='wrist_2_link'>
          <pose frame=''>0.817183 0.108841 0.176973 -3.14143 -0.015564 3.14094</pose>
          <velocity>-0.000475 -0.000124 -0.037831 -0.000105 0.048362 0.00149</velocity>
          <acceleration>0.176134 -0.074731 0.051482 -0.287019 -0.272523 0.53013</acceleration>
          <wrench>0.214708 -0.091096 0.062756 0 -0 0</wrench>
        </link>
        <link name='wrist_3_link'>
          <pose frame=''>0.81571 0.108827 0.082334 -3.14141 -0.015956 3.14095</pose>
          <velocity>-0.005044 -0.000136 -0.037759 4.8e-05 0.050128 0.00192</velocity>
          <acceleration>0.074861 -0.074655 0.053954 0.016882 -0.148596 1.39086</acceleration>
          <wrench>0.061749 -0.061579 0.044504 0 -0 0</wrench>
        </link>
      </model>
      <model name='table'>
        <pose frame=''>1.55819 1.24706 0 0 -0 0</pose>
        <scale>1 1 1</scale>
        <link name='link'>
          <pose frame=''>1.55819 1.24706 0 0 -0 0</pose>
          <velocity>0 0 0 0 -0 0</velocity>
          <acceleration>0 0 0 0 -0 0</acceleration>
          <wrench>0 0 0 0 -0 0</wrench>
        </link>
      </model>
      <model name='wood_cube_5cm'>
        <pose frame=''>-6.877 -106.098 -0.001001 0 -0 0.601383</pose>
        <scale>1 1 1</scale>
        <link name='link'>
          <pose frame=''>-6.877 -106.098 0.023999 0 -0 0.601383</pose>
          <velocity>0 0 0 0 -0 0</velocity>
          <acceleration>0 0 0 0 -0 0</acceleration>
          <wrench>0 0 0 0 -0 0</wrench>
        </link>
      </model>
      <light name='sun'>
        <pose frame=''>0 0 10 0 -0 0</pose>
      </light>
    </state>
    <gui fullscreen='0'>
      <camera name='user_camera'>
        <pose frame=''>3.15497 -3.11031 2.42285 0 0.311643 1.9042</pose>
        <view_controller>orbit</view_controller>
        <projection_type>perspective</projection_type>
      </camera>
    </gui>
  </world>
</sdf>
